Workbook

Sheet 00_README
B2: Digitaler Assistent – Szenario- und Nutzenmodell
B4: Zweck | C4: Kosten- und Nutzenanalyse für Digitalen Assistenten bei der Landi. 5 Szenarien: Copilot Studio, GCP Vertex AI, Azure Komponenten (GPT-5.1 CH North), Open Source Azure, GCP Custom. ZenAI entfernt. 6 priorisierte Use Cases (alle 100% generativ). 600 Nutzer · 6 Kernsysteme · 5-Jahres-TCO.
B5: Arbeitsweise | C5: 1) Annahmen in 02_INPUTS prüfen (bleiben von Landi bestätigt). 2) Szenario-Hebel in 03_SZENARIOS anpassen. 3) Ergebnisse in 01_EXEC_SUMMARY und 07_VALUE_CASE ablesen.
B6: Wichtiger Modellentscheid | C6: Die operative Landi-Top-down-Schätzung und die Workshop-Bottom-up-Schätzung werden bewusst parallel gezeigt. Der Basiscase nutzt die konservative Effizienzsicht; kommerzielle Upside ist standardmässig deaktiviert.
B7: Hinweis zu Preisen & Annahmen | C7: Microsoft- und Azure-Preise sind region-, vertrag- und FX-abhängig. Deshalb sind Preise als parametrisierbare Annahmen aufgebaut und die Quellen im Sheet 08_SOURCES dokumentiert.
B8: Hinweis | C8: Gelbe Zellen = editierbare Annahmen. Formeln sind schwarz/grün. Kommerzielle Upside kann in 02_INPUTS aktiviert werden.

Sheet 01_EXEC_SUMMARY
B2: Executive Summary – Szenariovergleich Digitaler Assistent
B4: 1) Executive Übersicht
B5: Kernaussage | C5: Copilot Studio | D5: Azure Komponenten | E5: Open Source auf Azure | F5: GCP Vertex AI | G5: GCP Kompontenten | H5: Kommentar
B6: Strategische Analyse | C6: GPT-5 MS-managed; Günstig wenn M365 Copilot; Custom Connectors nötig; keine CH-LLM-Residenz. | D6: GPT-5.1 in CH North; volle CH-Residenz; Token CHF 95/Mo; beste Wahl für GPT-5.1+CH+SAP/ERP. | E6: Llama 4/Phi-4; kein OpenAI-Lock-in; CH North möglich; LLM-Ops nötig; längste Delivery. | F6: GCP Agent Builder + Gemini 3.1; günstigstes OPEX korrigiert; keine CH-Residenz; GCP-Strategie. | G6: Cloud Run+ADK+Gemini direkt+Firestore; günstigstes all-in OPEX; keine CH-Residenz. | H6: Empfohlenes Zielnarrativ: Copilot = schneller Start; Azure = strategische Zielarchitektur; Open Source = Souveränitätsoption. Im v6-Modell wurde Copilot nicht mehr als rein cloud-native Abkürzung gerechnet, sondern für eine Hybrid-/On-Prem-Landschaft kalibriert.
B8: 2) Vergleich Kosten und Wertbeitrag der Szenarien
B9: Messgrösse | C9: Copilot Studio | D9: Azure Komp. (GPT-5.1 CH North) | E9: Open Source Azure | F9: GCP Vertex AI | G9: GCP Komponenten | H9: Kommentar
B10: Externe Personentage | C10: ='05_KOSTEN_MODELL'!C30 -> 91.375 | D10: ='05_KOSTEN_MODELL'!D30 -> 123.625 | E10: ='05_KOSTEN_MODELL'!E30 -> 129 | F10: ='05_KOSTEN_MODELL'!F30 -> 107.5 | G10: ='05_KOSTEN_MODELL'!G30 -> 118.25 | H10: Lieferaufwand extern
B11: Interne Personentage | C11: ='05_KOSTEN_MODELL'!C31 -> 34.85 | D11: ='05_KOSTEN_MODELL'!D31 -> 47.15 | E11: ='05_KOSTEN_MODELL'!E31 -> 49.2 | F11: ='05_KOSTEN_MODELL'!F31 -> 41 | G11: ='05_KOSTEN_MODELL'!G31 -> 45.1 | H11: Business-/IT-Last intern
B12: Implementierungsinvestition | C12: ='05_KOSTEN_MODELL'!C67 -> 849830 | D12: ='05_KOSTEN_MODELL'!D67 -> 1149770 | E12: ='05_KOSTEN_MODELL'!E67 -> 1199760 | F12: ='05_KOSTEN_MODELL'!F67 -> 999800 | G12: ='05_KOSTEN_MODELL'!G67 -> 1099780 | H12: Einmalige Investition
B13: Steady-state OPEX p.a. (Y4) | C13: ='05_KOSTEN_MODELL'!C70 -> 548669.63 | D13: ='05_KOSTEN_MODELL'!D70 -> 415234.36 | E13: ='05_KOSTEN_MODELL'!E70 -> 388869.03 | F13: ='05_KOSTEN_MODELL'!F70 -> 329073.66 | G13: ='05_KOSTEN_MODELL'!G70 -> 386245.33 | H13: Dauerbetrieb
B14: 5Y TCO | C14: ='05_KOSTEN_MODELL'!C69 -> 3305878.5 | D14: ='05_KOSTEN_MODELL'!D69 -> 3180398.3 | E14: ='05_KOSTEN_MODELL'!E69 -> 3134996.5 | F14: ='05_KOSTEN_MODELL'!F69 -> 2626950.9 | G14: ='05_KOSTEN_MODELL'!G69 -> 2994571.8 | H14: Investition + 5Y OPEX
B15: Konservatives Nutzenpotenzial p.a. | C15: ='07_VALUE_CASE'!C9 -> 1207439.5 | D15: ='07_VALUE_CASE'!D9 -> 1349491.2 | E15: ='07_VALUE_CASE'!E9 -> 1349491.2 | F15: ='07_VALUE_CASE'!F7 -> 1278465.3 | G15: ='07_VALUE_CASE'!G7 -> 1349491.2 | H15: Nach Szenario-Realisierung
B16: Kumulierter Nutzen über 5 Jahre | C16: ='07_VALUE_CASE'!C16 -> 4695598 | D16: ='07_VALUE_CASE'!D16 -> 5248021.3 | E16: ='07_VALUE_CASE'!E16 -> 5248021.3 | F16: ='07_VALUE_CASE'!F16 -> 4971809.6 | G16: ='07_VALUE_CASE'!G16 -> 5248021.3 | H16: Ramp-up berücksichtigt
B17: 5Y Nettowert | C17: ='07_VALUE_CASE'!C20 -> 1389719.5 | D17: ='07_VALUE_CASE'!D20 -> 2067623 | E17: ='07_VALUE_CASE'!E20 -> 2113024.8 | F17: ='07_VALUE_CASE'!F20 -> 2344858.7 | G17: ='07_VALUE_CASE'!G20 -> 2253449.4 | H17: Nutzen minus TCO
B18: Payback (Monate) | C18: ='07_VALUE_CASE'!C22 -> 15.480308 | D18: ='07_VALUE_CASE'!D22 -> 14.768145 | E18: ='07_VALUE_CASE'!E22 -> 14.987287 | F18: ='07_VALUE_CASE'!F22 -> 12.637145 | G18: ='07_VALUE_CASE'!G22 -> 13.700926 | H18: Steady-state-Payback
B20: 3) ROI Berechnung
B29: 4) Qualitative Scorecard
B30: Kriterium | C30: Copilot Studio | D30: Azure Komp. (GPT-5.1) | E30: Open Source Azure | F30: GCP Vertex AI | G30: GCP Custom | H30: Kommentar
B31: Schnelle Umsetzung | C31: ='03_SZENARIOS'!C38 -> 4 | D31: ='03_SZENARIOS'!D38 -> 4 | E31: ='03_SZENARIOS'!E38 -> 2 | F31: ='03_SZENARIOS'!F38 -> 4 | G31: ='03_SZENARIOS'!G38 -> 3 | H31: 5 = am schnellsten
B32: Flexibilität / Optimierbarkeit | C32: ='03_SZENARIOS'!C39 -> 2 | D32: ='03_SZENARIOS'!D39 -> 5 | E32: ='03_SZENARIOS'!E39 -> 5 | F32: ='03_SZENARIOS'!F39 -> 5 | G32: ='03_SZENARIOS'!G39 -> 5 | H32: 5 = am flexibelsten
B33: Integrationsfähigkeit | C33: ='03_SZENARIOS'!C40 -> 3 | D33: ='03_SZENARIOS'!D40 -> 4 | E33: ='03_SZENARIOS'!E40 -> 3 | F33: ='03_SZENARIOS'!F40 -> 4 | G33: ='03_SZENARIOS'!G40 -> 4 | H33: 5 = am einfachsten
B34: Governance / Controls | C34: ='03_SZENARIOS'!C41 -> 5 | D34: ='03_SZENARIOS'!D41 -> 4 | E34: ='03_SZENARIOS'!E41 -> 3 | F34: ='03_SZENARIOS'!F41 -> 3 | G34: ='03_SZENARIOS'!G41 -> 3 | H34: 5 = am stärksten
B35: Vendor Lock-in Risiko | C35: ='03_SZENARIOS'!C42 -> 1 | D35: ='03_SZENARIOS'!D42 -> 3 | E35: ='03_SZENARIOS'!E42 -> 5 | F35: ='03_SZENARIOS'!F42 -> 2 | G35: ='03_SZENARIOS'!G42 -> 3 | H35: 5 = niedrigstes Risiko
B36: Future-Readiness | C36: ='03_SZENARIOS'!C43 -> 2 | D36: ='03_SZENARIOS'!D43 -> 5 | E36: ='03_SZENARIOS'!E43 -> 5 | F36: ='03_SZENARIOS'!F43 -> 4 | G36: ='03_SZENARIOS'!G43 -> 5 | H36: 5 = höchste Zukunftsfähigkeit
B37: MCP-Readiness | C37: ='03_SZENARIOS'!C44 -> 2 | D37: ='03_SZENARIOS'!D44 -> 5 | E37: ='03_SZENARIOS'!E44 -> 5 | F37: ='03_SZENARIOS'!F44 -> 5 | G37: ='03_SZENARIOS'!G44 -> 5 | H37: 5 = offenste Architektur
B39: 5) Executive Empfehlung
B40: Wir empfehlen, den digitalen Assistenten auf GCP aufzubauen – mit einem schnellen Einstieg über Vertex AI und einem klaren Pfad in eine produktive Zielarchitektur. Strategischer Fit: Passt zur angestrebten LANDI / fenaco Zielarchitektur. Technisch machbar: Dynamics, SharePoint und weitere Umsysteme sind integrierbar. Ohne Sackgasse skalierbar: PoC, Pilot und produktiver Betrieb können auf derselben Plattform erfolgen. Zukunftsfähig: Mit einer offnene GCP Architektur lassen sich auch neue, unvorsehbare Entwicklungen integrieren

Sheet 02_INPUTS
B2: Integrierte Eingaben: Skalierung, Nutzung, Nutzen und kommerzielle Hebel
B4: Treiber | C4: Einheit | D4: Wert / Y1 | E4: Y2 | F4: Y3 | G4: Y4 | H4: Y5 | I4: Notiz / Quelle
B5: 1) Skalierung, Organisation und Basisgrössen
B6: Anzahl PoS | C6: Anzahl | D6: 193 | I6: Wie viele Landi Läden
B7: Anzahl Service-Mitarbeitende pro PoS | C7: Anzahl | D7: 3 | I7: Wie viele MA pro PoS
B8: Service-Center Nutzer / Mitarbeitende | C8: Anzahl | D8: 50 | I8: Anpassbar; bisherige Baseline.
B9: Zentrale Fachanwender / Experten | C9: Anzahl | D9: 25 | I9: Zusätzliche Power User.
B10: Totale potenzielle Nutzer | C10: Formel | D10: =D6*D7+D8+D9 -> 654 | I10: Formel aus Filialen und zentralen Rollen
B11: Arbeitstage pro Jahr | C11: Tage | D11: 312 | I11: Aus Landi-Annahmen
B12: Arbeitstage pro Monat | C12: Tage | D12: 21 | I12: Planungswert für Nutzungsmodell
B13: Betriebsstunden pro Tag | C13: Stunden | D13: 10 | I13: Näherungswert für Concurrency
B14: Planungshorizont | C14: Jahre | D14: 5 | I14: Standard im Modell
B15: USD/CHF Wechselkurs | C15: FX | D15: 0.8 | I15: Planungswert für Umrechnung öffentlicher USD-Preise
B17: 2) Nutzungs- und Adoptionsmodell
B18: Anteil monatlich aktiver Nutzer | C18: % Y1–Y5 | D18: 0.35 | E18: 0.6 | F18: 0.75 | G18: 0.9 | H18: 0.9 | I18: Ramp-up bis steady state
B19: Interaktionen pro aktivem Nutzer und Arbeitstag | C19: Anzahl | D19: 4 | I19: Mitarbeiter-Use-Cases in der Filiale / im SC
B20: Durchschnitt Input-Tokens pro Interaktion | C20: Token | D20: 2400 | I20: Text + Kontext
B21: Durchschnitt Output-Tokens pro Interaktion | C21: Token | D21: 500 | I21: Antwort + Begründung
B22: Anteil Bild-/Produktidentifikation | C22: % der Interaktionen | D22: 0.15 | I22: Produktidentifikation / visuelle Diagnose
B23: Zusätzliche Input-Tokens für Bildinteraktionen | C23: Token-Äquivalent | D23: 1200 | I23: Näherungswert
B24: Anteil RAG-/Retrieval-Interaktionen | C24: % der Interaktionen | D24: 0.6 | I24: Kontextzugriff auf Wissen und Systeme
B25: Anteil Interaktionen mit Aktion / Write-back | C25: % der Interaktionen | D25: 0.25 | I25: z. B. Fall vorbereiten, Lookup, Update
B26: Ablaufaktionen pro aktiver Aktionsinteraktion | C26: Anzahl | D26: 4 | I26: z. B. Connector-/Flow-Aktionen
B27: Spitzenlast-Multiplikator | C27: x | D27: 2.2 | I27: Für Peak-Token-/GPU-Dimensionierung
B29: 3) Komplexität und Kostensätze
B30: Zu integrierende Wissensquellen | C30: Anzahl | D30: 7 | I30: z. B. Knowledge Base, Blob, SharePoint
B31: Zu integrierende Kernsysteme | C31: Anzahl | D31: 6 | I31: PIM, MAM, ERP, CRM, etc.
B32: Anwendungsfälle Phase 1 | C32: Anzahl | D32: 4 | I32: Produkt identifizieren, Diagnose, Handlungsoptionen, etc.
B33: Sprachen / Märkte in Welle 1 | C33: Anzahl | D33: 2 | I33: Mehrsprachigkeit erhöht Design- und Testaufwand
B34: Sicherheits- / Compliance-Multiplikator | C34: x | D34: 1.15 | I34: Hebel auf Integrations-/Testaufwand
B35: Externer Tagessatz | C35: CHF / PD | D35: 2000 | I35: Gemischtes Delivery-Team
B36: Interner Projekt-Tagessatz | C36: CHF / PD | D36: 0 | I36: Business, IT, Security, UAT, Intern kein Kostensatz
B37: Bison Tagessatz | C37: CHF / PD | D37: =170*41/5 -> 1394 | I37: Bison Stundensatz
B38: Personalkosten Service / Filiale | C38: CHF / Stunde | D38: 50 | I38: User input
B39: Vollkostenähnlicher Satz Service / Technik | C39: CHF / Stunde | D39: 55 | I39: Für unnötige Serviceaufträge
B40: Service-Center / Admin Satz | C40: CHF / Stunde | D40: 60 | I40: Für Anfragen / Retouren / Admin
B41: Produktive Stunden pro FTE / Jahr | C41: Stunden | D41: 1800 | I41: Für FTE-Lens
B42: Monatskosten FTE Geschäft / Produkt | C42: CHF / Monat | D42: 14000 | I42: PO / Governance / Business Ownership
B43: Monatskosten FTE Plattform / Integration | C43: CHF / Monat | D43: 18000 | I43: Engineering / Integration / DevOps
B44: Monatskosten FTE Content / Wissen | C44: CHF / Monat | D44: 13000 | I44: Content Ops / Wissenspflege
...

Sheet 03_SZENARIOS
B2: Szenariologik, Preishebel, Delivery-Aufwand und qualitative Scorecard
B3: 5 Szenarien: Copilot (100% generativ), Azure Komponenten (GPT-5.1 CH North), Open Source Azure, GCP Vertex AI, GCP Custom. 100% generative Antworten.
B4: Treiber / Hebel | C4: Copilot Studio | D4: Azure Komponenten | E4: Open Source auf Azure | F4: GCP Vertex AI | G4: GCP Komponenten | H4: Kommentar
B5: Narrativ pro Szenario
B6: Positionierung | C6: Low-Code-Plattform; 100% generative Antworten; MS verwaltet LLM (GPT-4o); Custom Connectors für MAM/Agronet nötig; keine CH-LLM-Residenz; ideal wenn 600 Nutzer bereits M365 Copilot haben. | D6: Modulare Azure-Zielarchitektur; GPT-5.1 in Switzerland North bestätigt; volle CH-Datenresidenz; maximale Kontrolle über Prompts, RAG und Integrationen; Function Calling für alle 6 Systeme. | E6: Maximale Souveränität; selbst bestimmte LLM Modelle, welche über APIs genutzt werden | F6: GCP Agent Builder + Dialogflow CX + Gemini 3.1 Pro/Flash; managed Plattform; günstige Token-Kosten; keine CH-Datenresidenz (nur EU); ideal wenn GCP strategische Plattform. | G6: GCP Custom Stack: Cloud Run + Google ADK + Gemini API direkt + Firestore Vector Search; kein Vertex AI Search Overhead ($4/1K); günstigstes all-in OPEX; keine CH-Datenresidenz (nur EU); GCP-Engineering-Expertise nötig. | H6: Diese Narrative fliessen über die Realisierungsfaktoren und die qualitative Scorecard in die Bewertung ein.
B8: 1) Operating Model / Run Model
B9: Product Owner / Backlog (FTE) | C9: 0.3 | D9: 0.35 | E9: 0.4 | F9: 0.3 | G9: 0.35 | H9: Business Ownership / Governance
B10: Wissensmanagement / Content Ops (FTE) | C10: 0.35 | D10: 0.35 | E10: 0.4 | F10: 0.35 | G10: 0.35 | H10: Kuration, Qualität, Aktualität
B11: Plattform / Integration / (Entwicklung) (FTE) | C11: 0.4 | D11: 0.5 | E11: 0.6 | F11: 0.4 | G11: 0.5 | H11: Korrigiert OSS: 0.7 FTE Plattform/Integration (war: 1.5 FTE für GPU-Cluster-Betrieb). API-basierter Betrieb eliminiert: GPU-Cluster-Management, Inference-Server-Tuning (vLLM/TGI), CUDA/Driver-Updates, Model-Weight-Management, GPU-Autoscaling. Verbleibend: Orchestrierungscode (LangGraph/SK), RAG-Pipeline-Wartung, Integrationen (PIM/MAM/ERP/CRM), Security-Patching, CI/CD, Monitoring. 0.7 FTE = leicht höher als Azure (0.6 FTE) wegen mehr Open-Source-Tooling-Verwaltung. Quelle: Marktpraxis für API-basierte GenAI-Produktivitäts-Agents, 2025.
B12: QA / Analytics / Governance (FTE) | C12: 0.2 | D12: 0.25 | E12: 0.3 | F12: 0.2 | G12: 0.25 | H12: Quality, Reporting, Guardrails
B13: Externer Support / Managed Service | C13: 2000 | D13: 2500 | E13: 1500 | F13: 1500 | G13: 1500 | H13: Copilot/Azure: MS Support Plan. GCP: Google Support. OSS: Azure Dev Support + Community-Budget.
B14: Hypercare-Aufschlag auf FTE im Jahr 1 | C14: 0.2 | D14: 0.2 | E14: 0.25 | F14: 0.2 | G14: 0.2 | H14: Temporäre Mehrbelastung im ersten Jahr
B16: 2) LLM & Modellkosten / Plattform & Infrastrukturkosten
B17: LLM & ModellKosten (variable)
B18: Token Input-Preis (CHF / 1 Mio. Tokens) | C18: Credits → | D18: 2.5 | E18: 0.5 | F18: 1 | G18: 2 | H18: CHF/1M Input-Tokens. Copilot: Credits-Modell (keine Token-Preise). Azure berechnet mit GPT 5.4 / GPC Gemini 3.1 Pro
B19: Token Output-Preis (CHF / 1 Mio. Tokens) | C19: Credits → | D19: 15 | E19: 3 | F19: 6 | G19: 12 | H19: GCP Vertex: blended Gemini Flash 50%/Pro 50%. Azure: GPT-5.4 $15/M Out. OSS: Llama 4 (Foundry).
B20: Ø Copilot Credits / Interaktion | C20: 10 | D20: ← gilt für alle Szenarien | H20: 1 gen. Antwort (2) + 1.5 Agent Actions × 5 (7.5) + 0.1 AI-Tools × 1.5 (0.15)
B21: Copilot Credit-Preis (CHF / Credit, Capacity Pack) | C21: 0.0088 | D21: ← gilt für alle Szenarien | H21: USD 200 / 25'000 Credits × FX 0.80. PAYG = CHF 0.008.
B22: Plattform & Infrastruktur (montalich, fix) | C22: =SUM(C23:C34) -> 825 | D22: =SUM(D23:D34) -> 4137.1 | E22: =SUM(E23:E34) -> 1172.6 | F22: =SUM(F23:F34) -> 3206.5 | G22: =SUM(G23:G34) -> 3404.5
B23: Suche / RAG (Vector Search) | C23: 0 | D23: 1100 | E23: 245 | F23: 1250 | G23: 1250 | H23: Copilot: in Credits enthalten. GCP-V: Vertex AI Search ($4/1K, 103K Queries/Jahr). Azure: AI Search S1 2 SU. OSS: AI Search S1 1 SU. GCP-C: Firestore (nahezu gratis).
B24: API Gateway / Orchestrierung / Compute | C24: — | D24: 2300 | E24: 450 | F24: 1500 | G24: 1500 | H24: Copilot: Azure: APIM CHF 650 + Container Apps CHF 1'200. OSS: Container Apps CHF 450. GCP: Cloud Run ~CHF 150.
B25: Sessions / Dialogflow | C25: — | D25: — | E25: — | F25: 120 | G25: — | H25: GCP Vertex: Dialogflow CX $0.007/Session × 18'000 = ~CHF 120/Monat.
B26: State / Session Cache (Redis/Memorystore) | C26: — | D26: 180 | E26: 90 | F26: — | G26: 40 | H26: Azure: Redis C2 (6GB HA) CHF 180. OSS: Redis C1 (1GB) CHF 90. GCP Custom: Memorystore Basic CHF 40.
B27: Datenbank (Conversation History / State) | C27: — | D27: 30 | E27: 30 | F27: — | G27: 20 | H27: Azure & OSS: CosmosDB Serverless ~CHF 30. GCP Custom: Firestore CHF 20.
B28: Monitoring / Logging | C28: — | D28: 130 | E28: 70 | F28: 20 | G28: 20 | H28: Azure: Log Analytics ~55GB/Mt × $2.30/GB = CHF 130. GCP: Cloud Logging CHF 20. OSS: Log Analytics CHF 70.
B29: Storage (Dokumente, Backups, Registry) | C29: — | D29: 16 | E29: 16 | F29: 15 | G29: 15 | H29: Azure: Blob Hot 350GB = CHF 6 + Container Registry CHF 5 + Backups CHF 5. GCP: Cloud Storage CHF 15.
B30: Secrets / Key Management | C30: — | D30: 5 | E30: 5 | F30: — | G30: — | H30: Azure: Key Vault Standard CHF 5.
B31: Security / DDoS (Cloud Armor / API Shield) | C31: — | D31: — | E31: — | F31: 10 | G31: 10 | H31: GCP: Cloud Armor CHF 10.
B32: Custom Connector Hosting (für MAM/Agronet) | C32: 200 | D32: — | E32: — | F32: — | G32: — | H32: Copilot: SixOMC MAM & Agronet nicht als Standard-Power-Platform-Connector verfügbar.
B33: Basis-Plattform / Monat (paketiert / OSS) | C33: 550 | D33: 0 | E33: 160 | F33: 0 | G33: 240 | H33: Copilot: CHF 550/Mt (Power Platform). Azure: 0. OSS: 0.
B34: Contingency (10–12%) | C34: =SUM(C23:C33)*0.1 -> 75 | D34: =SUM(D23:D33)*0.1 -> 376.1 | E34: =SUM(E23:E33)*0.1 -> 106.6 | F34: =SUM(F23:F33)*0.1 -> 291.5 | G34: =SUM(G23:G33)*0.1 -> 309.5 | H34: Puffer für Preisänderungen, Lastspitzen, unvorhergesehene Kosten.
B37: 3) Qualitative Scorecard und Nutzen-Realisierung
B38: Schnelle Umsetzung bis Marktreife (1–5) | C38: 4 | D38: 4 | E38: 2 | F38: 4 | G38: 3 | H38: 5 = schnellste Time-to-Value
B39: Flexibilität / Optimierbarkeit (1–5) | C39: 2 | D39: 5 | E39: 5 | F39: 5 | G39: 5 | H39: 5 = höchste Tiefe / Modularität
B40: Integrationsfähigkeit (1–5) | C40: 3 | D40: 4 | E40: 3 | F40: 4 | G40: 4 | H40: Bei Hybrid-/On-Prem-Landschaft ist Copilot integrativ nicht mehr klar einfacher als Azure-Komponenten.
B41: Governance / Controls (1–5) | C41: 5 | D41: 4 | E41: 3 | F41: 3 | G41: 3 | H41: 5 = stärkste Governance
B42: Vendor Lock-in Risiko (1–5) | C42: 1 | D42: 3 | E42: 5 | F42: 2 | G42: 3 | H42: 5 = niedrigstes Lock-in-Risiko
B43: Future-Readiness / modulare Architektur (1–5) | C43: 2 | D43: 5 | E43: 5 | F43: 4 | G43: 5 | H43: 5 = höchste Zukunftsfähigkeit
B44: MCP-Readiness / Offenheit (1–5) | C44: 2 | D44: 5 | E44: 5 | F44: 5 | G44: 5 | H44: 5 = höchste Offenheit
B45: Realisierungsfaktor Effizienznutzen | C45: 0.85 | D45: 0.95 | E45: 0.95 | F45: 0.9 | G45: 0.95 | H45: Zukunftsfähigkeit und Abhängigkeitshebel
...

Sheet 04_PoC_MVP_Phasen
B2: Die Berechnungen sind aktuell auf externen Tagessätzen basierend ausgeführt
B4: PHASE 1 – PoC (Proof of Concept)
B5: Ziel: Technologie validieren in 6–8 Wochen. Kein Live-Systemzugriff – statische Daten und Uploads. 4 Use Cases vollständig gebaut und von SMEs bewertet. Go/No-Go Entscheid für MVP.
B6: Use Cases: UC1: Produkt identifizieren · UC2: Produktinfos bereitstellen · UC3: Diagnose · UC4: Handlungsoptionen
B7: Aufgabe / Deliverable | C7: Wochen | D7: Projektleitung / Delivery Lead | E7: Fachlead / Product Owner Landi | F7: Key User / SMEs Landi | G7: Solution Architect / Lead Engineer | H7: AI Engineer / Data Scientist | I7: Data Engineer | J7: Business Analyst / Quality Assurance | K7: Total PT | L7: Ext. Kosten CHF
B8: P0 Projektsteup PoC und PMO | C8: =ROUNDUP(MAX(D8:J8)/5,0) -> 1 | D8: =SUMIFS($T$73:$T$131,$P$73:$P$131,LEFT($B8,2),$R$73:$R$131,D$7) -> 5 | E8: =SUMIFS($T$73:$T$131,$P$73:$P$131,LEFT($B8,2),$R$73:$R$131,E$7) -> 1 | F8: =SUMIFS($T$73:$T$131,$P$73:$P$131,LEFT($B8,2),$R$73:$R$131,F$7) -> 1 | G8: =SUMIFS($T$73:$T$131,$P$73:$P$131,LEFT($B8,2),$R$73:$R$131,G$7) -> 0 | H8: =SUMIFS($T$73:$T$131,$P$73:$P$131,LEFT($B8,2),$R$73:$R$131,H$7) -> 0 | I8: =SUMIFS($T$73:$T$131,$P$73:$P$131,LEFT($B8,2),$R$73:$R$131,I$7) -> 0 | J8: =SUMIFS($T$73:$T$131,$P$73:$P$131,LEFT($B8,2),$R$73:$R$131,J$7) -> 0 | K8: =SUM(D8:J8) -> 7 | L8: =SUM(D8,G8,H8,I8,J8)*'02_INPUTS'!$D$35 -> 10000
B9: P1 Ground Truth & Kalibrierung | C9: =ROUNDUP(MAX(D9:J9)/5,0) -> 2 | D9: =SUMIFS($T$73:$T$131,$P$73:$P$131,LEFT($B9,2),$R$73:$R$131,D$7) -> 2 | E9: =SUMIFS($T$73:$T$131,$P$73:$P$131,LEFT($B9,2),$R$73:$R$131,E$7) -> 4 | F9: =SUMIFS($T$73:$T$131,$P$73:$P$131,LEFT($B9,2),$R$73:$R$131,F$7) -> 10 | G9: =SUMIFS($T$73:$T$131,$P$73:$P$131,LEFT($B9,2),$R$73:$R$131,G$7) -> 1 | H9: =SUMIFS($T$73:$T$131,$P$73:$P$131,LEFT($B9,2),$R$73:$R$131,H$7) -> 0.5 | I9: =SUMIFS($T$73:$T$131,$P$73:$P$131,LEFT($B9,2),$R$73:$R$131,I$7) -> 0.5 | J9: =SUMIFS($T$73:$T$131,$P$73:$P$131,LEFT($B9,2),$R$73:$R$131,J$7) -> 5 | K9: =SUM(D9:J9) -> 23 | L9: =SUM(D9,G9,H9,I9,J9)*'02_INPUTS'!$D$35 -> 18000
B10: P2 Detaildesign & Datenvorbereitung | C10: =ROUNDUP(MAX(D10:J10)/5,0) -> 1 | D10: =SUMIFS($T$73:$T$131,$P$73:$P$131,LEFT($B10,2),$R$73:$R$131,D$7) -> 1 | E10: =SUMIFS($T$73:$T$131,$P$73:$P$131,LEFT($B10,2),$R$73:$R$131,E$7) -> 2 | F10: =SUMIFS($T$73:$T$131,$P$73:$P$131,LEFT($B10,2),$R$73:$R$131,F$7) -> 2 | G10: =SUMIFS($T$73:$T$131,$P$73:$P$131,LEFT($B10,2),$R$73:$R$131,G$7) -> 3 | H10: =SUMIFS($T$73:$T$131,$P$73:$P$131,LEFT($B10,2),$R$73:$R$131,H$7) -> 3.5 | I10: =SUMIFS($T$73:$T$131,$P$73:$P$131,LEFT($B10,2),$R$73:$R$131,I$7) -> 3 | J10: =SUMIFS($T$73:$T$131,$P$73:$P$131,LEFT($B10,2),$R$73:$R$131,J$7) -> 1.5 | K10: =SUM(D10:J10) -> 16 | L10: =SUM(D10,G10,H10,I10,J10)*'02_INPUTS'!$D$35 -> 24000
B11: P3 Runtime & Basisplattform | C11: =ROUNDUP(MAX(D11:J11)/5,0) -> 2 | D11: =SUMIFS($T$73:$T$131,$P$73:$P$131,LEFT($B11,2),$R$73:$R$131,D$7) -> 0.5 | E11: =SUMIFS($T$73:$T$131,$P$73:$P$131,LEFT($B11,2),$R$73:$R$131,E$7) -> 0.5 | F11: =SUMIFS($T$73:$T$131,$P$73:$P$131,LEFT($B11,2),$R$73:$R$131,F$7) -> 0.5 | G11: =SUMIFS($T$73:$T$131,$P$73:$P$131,LEFT($B11,2),$R$73:$R$131,G$7) -> 2 | H11: =SUMIFS($T$73:$T$131,$P$73:$P$131,LEFT($B11,2),$R$73:$R$131,H$7) -> 6.5 | I11: =SUMIFS($T$73:$T$131,$P$73:$P$131,LEFT($B11,2),$R$73:$R$131,I$7) -> 1.5 | J11: =SUMIFS($T$73:$T$131,$P$73:$P$131,LEFT($B11,2),$R$73:$R$131,J$7) -> 1.5 | K11: =SUM(D11:J11) -> 13 | L11: =SUM(D11,G11,H11,I11,J11)*'02_INPUTS'!$D$35 -> 24000
B12: P4 Agenten-Implementierung | C12: =ROUNDUP(MAX(D12:J12)/5,0) -> 4 | D12: =SUMIFS($T$73:$T$131,$P$73:$P$131,LEFT($B12,2),$R$73:$R$131,D$7) -> 10 | E12: =SUMIFS($T$73:$T$131,$P$73:$P$131,LEFT($B12,2),$R$73:$R$131,E$7) -> 4 | F12: =SUMIFS($T$73:$T$131,$P$73:$P$131,LEFT($B12,2),$R$73:$R$131,F$7) -> 4 | G12: =SUMIFS($T$73:$T$131,$P$73:$P$131,LEFT($B12,2),$R$73:$R$131,G$7) -> 3 | H12: =SUMIFS($T$73:$T$131,$P$73:$P$131,LEFT($B12,2),$R$73:$R$131,H$7) -> 16.5 | I12: =SUMIFS($T$73:$T$131,$P$73:$P$131,LEFT($B12,2),$R$73:$R$131,I$7) -> 4 | J12: =SUMIFS($T$73:$T$131,$P$73:$P$131,LEFT($B12,2),$R$73:$R$131,J$7) -> 6 | K12: =SUM(D12:J12) -> 47.5 | L12: =SUM(D12,G12,H12,I12,J12)*'02_INPUTS'!$D$35 -> 79000
B13: UC1: Produkt identifizieren
B14: UC2: Produktinformationen bereitstellen | V14: 40000
B15: UC3: Diagnose stellen | V15: 27000
B16: UC4: Handlungsoptionen | V16: 22000
B17: P5 Validierung & Tuning | C17: =ROUNDUP(MAX(D17:J17)/5,0) -> 2 | D17: =SUMIFS($T$73:$T$131,$P$73:$P$131,LEFT($B17,2),$R$73:$R$131,D$7) -> 5 | E17: =SUMIFS($T$73:$T$131,$P$73:$P$131,LEFT($B17,2),$R$73:$R$131,E$7) -> 3 | F17: =SUMIFS($T$73:$T$131,$P$73:$P$131,LEFT($B17,2),$R$73:$R$131,F$7) -> 6 | G17: =SUMIFS($T$73:$T$131,$P$73:$P$131,LEFT($B17,2),$R$73:$R$131,G$7) -> 2 | H17: =SUMIFS($T$73:$T$131,$P$73:$P$131,LEFT($B17,2),$R$73:$R$131,H$7) -> 9 | I17: =SUMIFS($T$73:$T$131,$P$73:$P$131,LEFT($B17,2),$R$73:$R$131,I$7) -> 1.5 | J17: =SUMIFS($T$73:$T$131,$P$73:$P$131,LEFT($B17,2),$R$73:$R$131,J$7) -> 4.5 | K17: =SUM(D17:J17) -> 31 | L17: =SUM(D17,G17,H17,I17,J17)*'02_INPUTS'!$D$35 -> 44000 | V17: 80000
B18: RAGAS-Metriken, SME-Review, Gap-Liste | V18: 52000
B19: P6 Abschluss & MVP-Entscheid | C19: =ROUNDUP(MAX(D19:J19)/5,0) -> 1 | D19: =SUMIFS($T$73:$T$131,$P$73:$P$131,LEFT($B19,2),$R$73:$R$131,D$7) -> 1 | E19: =SUMIFS($T$73:$T$131,$P$73:$P$131,LEFT($B19,2),$R$73:$R$131,E$7) -> 0.5 | F19: =SUMIFS($T$73:$T$131,$P$73:$P$131,LEFT($B19,2),$R$73:$R$131,F$7) -> 0.5 | G19: =SUMIFS($T$73:$T$131,$P$73:$P$131,LEFT($B19,2),$R$73:$R$131,G$7) -> 1 | H19: =SUMIFS($T$73:$T$131,$P$73:$P$131,LEFT($B19,2),$R$73:$R$131,H$7) -> 2 | I19: =SUMIFS($T$73:$T$131,$P$73:$P$131,LEFT($B19,2),$R$73:$R$131,I$7) -> 0.5 | J19: =SUMIFS($T$73:$T$131,$P$73:$P$131,LEFT($B19,2),$R$73:$R$131,J$7) -> 0.5 | K19: =SUM(D19:J19) -> 6 | L19: =SUM(D19,G19,H19,I19,J19)*'02_INPUTS'!$D$35 -> 10000 | V19: 10000
B20: P7 PoC-Dokumentation & Go/No-Go Vorlage | C20: =ROUNDUP(MAX(D20:J20)/5,0) -> 1 | D20: =SUMIFS($T$73:$T$131,$P$73:$P$131,LEFT($B20,2),$R$73:$R$131,D$7) -> 3 | E20: =SUMIFS($T$73:$T$131,$P$73:$P$131,LEFT($B20,2),$R$73:$R$131,E$7) -> 2 | F20: =SUMIFS($T$73:$T$131,$P$73:$P$131,LEFT($B20,2),$R$73:$R$131,F$7) -> 0 | G20: =SUMIFS($T$73:$T$131,$P$73:$P$131,LEFT($B20,2),$R$73:$R$131,G$7) -> 0 | H20: =SUMIFS($T$73:$T$131,$P$73:$P$131,LEFT($B20,2),$R$73:$R$131,H$7) -> 0 | I20: =SUMIFS($T$73:$T$131,$P$73:$P$131,LEFT($B20,2),$R$73:$R$131,I$7) -> 0 | J20: =SUMIFS($T$73:$T$131,$P$73:$P$131,LEFT($B20,2),$R$73:$R$131,J$7) -> 0 | K20: =SUM(D20:J20) -> 5 | L20: =SUM(D20,G20,H20,I20,J20)*'02_INPUTS'!$D$35 -> 6000 | V20: 20’000
B21: Einmahlige Software / Entwicklung Gebühr | L21: 35000 | V21: =SUM(V14:V20) -> 231000
B22: PHASE TOTAL | D22: =SUM(D17:D20,D8:D12) -> 27.5 | E22: =SUM(E17:E20,E8:E12) -> 17 | F22: =SUM(F17:F20,F8:F12) -> 24 | G22: =SUM(G17:G20,G8:G12) -> 12 | H22: =SUM(H17:H20,H8:H12) -> 38 | I22: =SUM(I17:I20,I8:I12) -> 11 | J22: =SUM(J17:J20,J8:J12) -> 19 | K22: =SUM(D22:J22) -> 148.5 | L22: =SUM(L8:L21) -> 250000
B23: Externe PT: 56 PT · Ext. Kosten CHF 2'000/PT: CHF 112,000 · SME intern: 17 PT · Total PT: 73 PT
B26: PHASE 2 – MVP (Minimum Viable Product)
B27: Ziel: Alle 8 Use Cases produktionsreif in 14–18 Wochen. 6 Live-Integrationen (PIM, MAM, ERP, Agronet, Odoo, SharePoint). Security-Audit, End-to-End-Testing, Rollout auf 600 Nutzer.
B28: Use Cases: UC1: Produkt identifizieren · UC2: Produktinfos bereitstellen · UC3: Diagnose · UC4: Handlungsoptionen · UC5: Ersatzteil · UC6: Garantie · UC7: Case vorbereiten · UC8: Dokumentation
B29: Aufgabe / Deliverable | C29: Wochen | D29: Projektleitung / Delivery Lead | E29: Fachlead / Product Owner Landi | F29: Key User / SMEs Landi | G29: Solution Architect / Cloud Engineer | H29: AI Engineer / Data Scientist | I29: Data Engineer | J29: Business Analyst / Quality Assurance | K29: Total PT | L29: Ext. Kosten CHF
B30: ── Projektstart und Organisation ────── | L30: =SUM(L31:L34) -> 190800
B31: Architektur & Security Design | C31: =ROUNDUP(MAX(D31:J31)/5,0) -> 1 | D31: 5 | E31: 2 | F31: 2 | G31: 2 | H31: 2 | I31: 0 | J31: 0 | K31: =SUM(C31:J31) -> 14 | L31: =SUM(D31,G31,H31,I31,J31)*'02_INPUTS'!$D$35 -> 18000
B32: CH-Residenz, IAM, Netzwerk, Audit-Log | C32: =ROUNDUP(MAX(D32:J32)/5,0) -> 1 | D32: 2 | E32: 1 | F32: 1 | G32: 1 | H32: 0 | I32: 0 | J32: 0 | K32: =SUM(C32:J32) -> 6 | L32: =SUM(D32,G32,H32,I32,J32)*'02_INPUTS'!$D$35 -> 6000
B33: Szenario GCP Vertex zu GCP Migration | C33: =ROUNDUP(MAX(D33:J33)/5,0) -> 2 | D33: 5 | E33: 0 | F33: 0 | G33: 10 | H33: 5 | I33: 10 | J33: 5 | K33: =SUM(C33:J33) -> 37 | L33: =SUM(D33,G33,H33,I33,J33)*'02_INPUTS'!$D$35 -> 70000
B34: Projektarbeit, Abstimmung und Kommunikation | C34: =ROUNDUP(MAX(D34:J34)/5,0) -> 3 | D34: =SUM(D36:D55)*0.2 -> 8.6 | E34: =SUM(E36:E55)*0.2 -> 9.8 | F34: =SUM(F36:F55)*0.2 -> 9.2 | G34: =SUM(G36:G55)*0.2 -> 13.6 | H34: =SUM(H36:H55)*0.2 -> 10.2 | I34: =SUM(I36:I55)*0.2 -> 9.4 | J34: =SUM(J36:J55)*0.2 -> 6.6 | K34: =SUM(D34:J34) -> 67.4 | L34: =SUM(D34,G34,H34,I34,J34)*'02_INPUTS'!$D$35 -> 96800
B35: ── INTEGRATIONEN ─────────────── | C35: =ROUNDUP(MAX(D35:J35)/5,0) -> 0 | D35: 0 | E35: 0 | F35: 0 | G35: 0 | H35: 0 | I35: 0 | K35: =SUM(C35:J35) -> 0 | L35: =SUM(L36:L41) -> 118000
B36: Integration: PIM – Elytra (Produktdaten) | C36: =ROUNDUP(MAX(D36:J36)/5,0) -> 2 | D36: 1 | E36: 2 | F36: 6 | G36: 5 | H36: 2 | I36: 2 | J36: 0 | K36: =SUM(C36:J36) -> 20 | L36: =SUM(D36,G36,H36,I36,J36)*'02_INPUTS'!$D$35 -> 20000
B37: Integration: MAM – SixOMC (Assets/Bilder) | C37: =ROUNDUP(MAX(D37:J37)/5,0) -> 1 | D37: 1 | E37: 2 | F37: 5 | G37: 5 | H37: 2 | I37: 2 | J37: 0 | K37: =SUM(C37:J37) -> 18 | L37: =SUM(D37,G37,H37,I37,J37)*'02_INPUTS'!$D$35 -> 20000
B38: Integration: ERP – B4LCH (Garantie/Auftr.) | C38: =ROUNDUP(MAX(D38:J38)/5,0) -> 2 | D38: 1 | E38: 3 | F38: 8 | G38: 5 | H38: 2 | I38: 3 | J38: 0 | K38: =SUM(C38:J38) -> 24 | L38: =SUM(D38,G38,H38,I38,J38)*'02_INPUTS'!$D$35 -> 22000
B39: Integration: Agronet (Middleware) | C39: =ROUNDUP(MAX(D39:J39)/5,0) -> 2 | D39: 1 | E39: 2 | F39: 6 | G39: 5 | H39: 2 | I39: 2 | J39: 0 | K39: =SUM(C39:J39) -> 20 | L39: =SUM(D39,G39,H39,I39,J39)*'02_INPUTS'!$D$35 -> 20000
B40: Integration: Odoo (Endkundenstamm) | C40: =ROUNDUP(MAX(D40:J40)/5,0) -> 1 | D40: 1 | E40: 1 | F40: 3 | G40: 5 | H40: 2 | I40: 1 | J40: 0 | K40: =SUM(C40:J40) -> 14 | L40: =SUM(D40,G40,H40,I40,J40)*'02_INPUTS'!$D$35 -> 18000
B41: Integration: SharePoint (erweitert) | C41: =ROUNDUP(MAX(D41:J41)/5,0) -> 1 | D41: 1 | E41: 1 | F41: 2 | G41: 5 | H41: 2 | I41: 1 | J41: 0 | K41: =SUM(C41:J41) -> 13 | L41: =SUM(D41,G41,H41,I41,J41)*'02_INPUTS'!$D$35 -> 18000
B42: ── USE CASES ─────────────────── | C42: =ROUNDUP(MAX(D42:J42)/5,0) -> 0 | D42: 0 | E42: 0 | F42: 0 | G42: 0 | H42: 0 | I42: 0 | K42: =SUM(C42:J42) -> 0 | L42: =SUM(L43:L50) -> 242000
B43: UC1: Produkt identifizieren | C43: =ROUNDUP(MAX(D43:J43)/5,0) -> 1 | D43: 3 | E43: 3 | F43: 1 | G43: 2 | H43: 4 | I43: 3 | J43: 2 | K43: =SUM(C43:J43) -> 19 | L43: =SUM(D43,G43,H43,I43,J43)*'02_INPUTS'!$D$35 -> 28000
B44: UC2: Produktinfos bereitstellen | C44: =ROUNDUP(MAX(D44:J44)/5,0) -> 1 | D44: 3 | E44: 3 | F44: 1 | G44: 2 | H44: 4 | I44: 3 | J44: 2 | K44: =SUM(C44:J44) -> 19 | L44: =SUM(D44,G44,H44,I44,J44)*'02_INPUTS'!$D$35 -> 28000
...

Sheet 05_KOSTEN_MODELL
B2: Kostenmodell: Usage, Implementierung, OPEX und 5Y TCO
B4: 1) Usage- und Kapazitätsbaseline
B5: Treiber | C5: Y1 | D5: Y2 | E5: Y3 | F5: Y4 | G5: Y5 | H5: Kommentar
B6: Potenzielle Nutzer | C6: ='02_INPUTS'!D10 -> 654 | D6: ='02_INPUTS'!D10 -> 654 | E6: ='02_INPUTS'!D10 -> 654 | F6: ='02_INPUTS'!D10 -> 654 | G6: ='02_INPUTS'!D10 -> 654 | H6: Gesamtnutzer aus Input-Sheet
B7: Aktive Nutzerquote | C7: ='02_INPUTS'!D18 -> 0.35 | D7: ='02_INPUTS'!E18 -> 0.6 | E7: ='02_INPUTS'!F18 -> 0.75 | F7: ='02_INPUTS'!G18 -> 0.9 | G7: ='02_INPUTS'!H18 -> 0.9 | H7: Ramp-up der Adoption
B8: Monatlich aktive Nutzer | C8: =C6*C7 -> 228.9 | D8: =D6*D7 -> 392.4 | E8: =E6*E7 -> 490.5 | F8: =F6*F7 -> 588.6 | G8: =G7*G6 -> 588.6 | H8: Monatlich aktive Nutzer
B9: Jährliche Interaktionen | C9: =C$8*'02_INPUTS'!$D$19*'02_INPUTS'!$D$11*'02_INPUTS'!$D$26 -> 1142668.8 | D9: =D$8*'02_INPUTS'!$D$19*'02_INPUTS'!$D$11*'02_INPUTS'!$D$26 -> 1958860.8 | E9: =E$8*'02_INPUTS'!$D$19*'02_INPUTS'!$D$11*'02_INPUTS'!$D$26 -> 2448576 | F9: =F$8*'02_INPUTS'!$D$19*'02_INPUTS'!$D$11*'02_INPUTS'!$D$26 -> 2938291.2 | G9: =G$8*'02_INPUTS'!$D$19*'02_INPUTS'!$D$11*'02_INPUTS'!$D$26 -> 2938291.2 | H9: Treiber für variable Kosten und Nutzenramp-up
B10: Jährliche Input-Tokens | C10: =C9*('02_INPUTS'!D20+'02_INPUTS'!D22*'02_INPUTS'!D23) -> 2.9480855e+09 | D10: =D9*('02_INPUTS'!D20+'02_INPUTS'!D22*'02_INPUTS'!D23) -> 5.0538609e+09 | E10: =E9*('02_INPUTS'!D20+'02_INPUTS'!D22*'02_INPUTS'!D23) -> 6317326080 | F10: =F9*('02_INPUTS'!D20+'02_INPUTS'!D22*'02_INPUTS'!D23) -> 7.5807913e+09 | G10: =G9*('02_INPUTS'!D20+'02_INPUTS'!D22*'02_INPUTS'!D23) -> 7.5807913e+09 | H10: Text + bildbezogene Zusatztokens
B11: Jährliche Output-Tokens | C11: =C9*'02_INPUTS'!D21 -> 5.713344e+08 | D11: =D9*'02_INPUTS'!D21 -> 9.794304e+08 | E11: =E9*'02_INPUTS'!D21 -> 1224288000 | F11: =F9*'02_INPUTS'!D21 -> 1469145600 | G11: =G9*'02_INPUTS'!D21 -> 1469145600 | H11: LLM Output
B12: Jährliche Retrieval-/RAG-Requests | C12: =C9*'02_INPUTS'!D24 -> 685601.28 | D12: =D9*'02_INPUTS'!D24 -> 1175316.5 | E12: =E9*'02_INPUTS'!D24 -> 1469145.6 | F12: =F9*'02_INPUTS'!D24 -> 1762974.7 | G12: =G9*'02_INPUTS'!D24 -> 1762974.7 | H12: Requests an Retrieval / Search / Vector
B13: Jährliche Interaktionen mit Aktion | C13: =C9*'02_INPUTS'!D25 -> 285667.2 | D13: =D9*'02_INPUTS'!D25 -> 489715.2 | E13: =E9*'02_INPUTS'!D25 -> 612144 | F13: =F9*'02_INPUTS'!D25 -> 734572.8 | G13: =G9*'02_INPUTS'!D25 -> 734572.8 | H13: Interaktionen, die einen Write-back / Tool Call auslösen
B14: Jährliche Flow-/Ablaufaktionen | C14: =C13*'02_INPUTS'!D26 -> 1142668.8 | D14: =D13*'02_INPUTS'!D26 -> 1958860.8 | E14: =E13*'02_INPUTS'!D26 -> 2448576 | F14: =F13*'02_INPUTS'!D26 -> 2938291.2 | G14: =G13*'02_INPUTS'!D26 -> 2938291.2 | H14: Für Flow-/Action-basierte Plattformlogik
B15: Peak Interaktionen pro Stunde | C15: =C9/('02_INPUTS'!D12*12*'02_INPUTS'!D13)*'02_INPUTS'!D27 -> 997.568 | D15: =D9/('02_INPUTS'!D12*12*'02_INPUTS'!D13)*'02_INPUTS'!D27 -> 1710.1166 | E15: =E9/('02_INPUTS'!D12*12*'02_INPUTS'!D13)*'02_INPUTS'!D27 -> 2137.6457 | F15: =F9/('02_INPUTS'!D12*12*'02_INPUTS'!D13)*'02_INPUTS'!D27 -> 2565.1749 | G15: =G9/('02_INPUTS'!D12*12*'02_INPUTS'!D13)*'02_INPUTS'!D27 -> 2565.1749 | H15: Hilft bei Kapazitäts- und GPU-Abschätzung
B16: Peak Tokens pro Sekunde | C16: =C15*(('02_INPUTS'!D20+'02_INPUTS'!D22*'02_INPUTS'!D23)+'02_INPUTS'!D21)/3600 -> 853.47484 | D16: =D15*(('02_INPUTS'!D20+'02_INPUTS'!D22*'02_INPUTS'!D23)+'02_INPUTS'!D21)/3600 -> 1463.0997 | E16: =E15*(('02_INPUTS'!D20+'02_INPUTS'!D22*'02_INPUTS'!D23)+'02_INPUTS'!D21)/3600 -> 1828.8747 | F16: =F15*(('02_INPUTS'!D20+'02_INPUTS'!D22*'02_INPUTS'!D23)+'02_INPUTS'!D21)/3600 -> 2194.6496 | G16: =G15*(('02_INPUTS'!D20+'02_INPUTS'!D22*'02_INPUTS'!D23)+'02_INPUTS'!D21)/3600 -> 2194.6496 | H16: Relevant für OSS-GPU-Sizing
B18: 2) Implementierungsinvestition
B19: Kostenbaustein | C19: Copilot Studio | D19: Azure Komponenten | E19: Open Source auf Azure | F19: GCP Vertex AI | G19: GCP Komponenten | H19: Kommentar
B20: PoC Kosten
B21: P0 Projektsteup PoC und PMO | C21: =VLOOKUP($B21,'04_PoC_MVP_Phasen'!$B$7:$L$22,11,FALSE)*'04_PoC_MVP_Phasen'!$D$64 -> 8500 | D21: =VLOOKUP($B21,'04_PoC_MVP_Phasen'!$B$7:$L$22,11,FALSE)*'04_PoC_MVP_Phasen'!$D$66 -> 11500 | E21: =VLOOKUP($B21,'04_PoC_MVP_Phasen'!$B$7:$L$22,11,FALSE)*'04_PoC_MVP_Phasen'!$D$67 -> 12000 | F21: =VLOOKUP($B21,'04_PoC_MVP_Phasen'!$B$7:$L$22,11,FALSE)*'04_PoC_MVP_Phasen'!$D$65 -> 10000 | G21: =VLOOKUP($B21,'04_PoC_MVP_Phasen'!$B$7:$L$22,11,FALSE)*'04_PoC_MVP_Phasen'!$D$68 -> 11000 | H21: Basis-PD
B22: P1 Ground Truth & Kalibrierung | C22: =VLOOKUP($B22,'04_PoC_MVP_Phasen'!$B$7:$L$22,11,FALSE)*'04_PoC_MVP_Phasen'!$D$64 -> 15300 | D22: =VLOOKUP($B22,'04_PoC_MVP_Phasen'!$B$7:$L$22,11,FALSE)*'04_PoC_MVP_Phasen'!$D$66 -> 20700 | E22: =VLOOKUP($B22,'04_PoC_MVP_Phasen'!$B$7:$L$22,11,FALSE)*'04_PoC_MVP_Phasen'!$D$67 -> 21600 | F22: =VLOOKUP($B22,'04_PoC_MVP_Phasen'!$B$7:$L$22,11,FALSE)*'04_PoC_MVP_Phasen'!$D$65 -> 18000 | G22: =VLOOKUP($B22,'04_PoC_MVP_Phasen'!$B$7:$L$22,11,FALSE)*'04_PoC_MVP_Phasen'!$D$68 -> 19800 | H22: Use cases und Sprach-Multiplikator
B23: P2 Detaildesign & Datenvorbereitung | C23: =VLOOKUP($B23,'04_PoC_MVP_Phasen'!$B$7:$L$22,11,FALSE)*'04_PoC_MVP_Phasen'!$D$64 -> 20400 | D23: =VLOOKUP($B23,'04_PoC_MVP_Phasen'!$B$7:$L$22,11,FALSE)*'04_PoC_MVP_Phasen'!$D$66 -> 27600 | E23: =VLOOKUP($B23,'04_PoC_MVP_Phasen'!$B$7:$L$22,11,FALSE)*'04_PoC_MVP_Phasen'!$D$67 -> 28800 | F23: =VLOOKUP($B23,'04_PoC_MVP_Phasen'!$B$7:$L$22,11,FALSE)*'04_PoC_MVP_Phasen'!$D$65 -> 24000 | G23: =VLOOKUP($B23,'04_PoC_MVP_Phasen'!$B$7:$L$22,11,FALSE)*'04_PoC_MVP_Phasen'!$D$68 -> 26400 | H23: Systeme x Security-Multiplikator x Hybrid-/On-Prem-Faktor
B24: P3 Runtime & Basisplattform | C24: =VLOOKUP($B24,'04_PoC_MVP_Phasen'!$B$7:$L$22,11,FALSE)*'04_PoC_MVP_Phasen'!$D$64 -> 20400 | D24: =VLOOKUP($B24,'04_PoC_MVP_Phasen'!$B$7:$L$22,11,FALSE)*'04_PoC_MVP_Phasen'!$D$66 -> 27600 | E24: =VLOOKUP($B24,'04_PoC_MVP_Phasen'!$B$7:$L$22,11,FALSE)*'04_PoC_MVP_Phasen'!$D$67 -> 28800 | F24: =VLOOKUP($B24,'04_PoC_MVP_Phasen'!$B$7:$L$22,11,FALSE)*'04_PoC_MVP_Phasen'!$D$65 -> 24000 | G24: =VLOOKUP($B24,'04_PoC_MVP_Phasen'!$B$7:$L$22,11,FALSE)*'04_PoC_MVP_Phasen'!$D$68 -> 26400 | H24: Wissensquellen
B25: P4 Agenten-Implementierung | C25: =VLOOKUP($B25,'04_PoC_MVP_Phasen'!$B$7:$L$22,11,FALSE)*'04_PoC_MVP_Phasen'!$D$64 -> 67150 | D25: =VLOOKUP($B25,'04_PoC_MVP_Phasen'!$B$7:$L$22,11,FALSE)*'04_PoC_MVP_Phasen'!$D$66 -> 90850 | E25: =VLOOKUP($B25,'04_PoC_MVP_Phasen'!$B$7:$L$22,11,FALSE)*'04_PoC_MVP_Phasen'!$D$67 -> 94800 | F25: =VLOOKUP($B25,'04_PoC_MVP_Phasen'!$B$7:$L$22,11,FALSE)*'04_PoC_MVP_Phasen'!$D$65 -> 79000 | G25: =VLOOKUP($B25,'04_PoC_MVP_Phasen'!$B$7:$L$22,11,FALSE)*'04_PoC_MVP_Phasen'!$D$68 -> 86900 | H25: Basis x Security-Multiplikator
B26: P5 Validierung & Tuning | C26: =VLOOKUP($B26,'04_PoC_MVP_Phasen'!$B$7:$L$22,11,FALSE)*'04_PoC_MVP_Phasen'!$D$64 -> 37400 | D26: =VLOOKUP($B26,'04_PoC_MVP_Phasen'!$B$7:$L$22,11,FALSE)*'04_PoC_MVP_Phasen'!$D$66 -> 50600 | E26: =VLOOKUP($B26,'04_PoC_MVP_Phasen'!$B$7:$L$22,11,FALSE)*'04_PoC_MVP_Phasen'!$D$67 -> 52800 | F26: =VLOOKUP($B26,'04_PoC_MVP_Phasen'!$B$7:$L$22,11,FALSE)*'04_PoC_MVP_Phasen'!$D$65 -> 44000 | G26: =VLOOKUP($B26,'04_PoC_MVP_Phasen'!$B$7:$L$22,11,FALSE)*'04_PoC_MVP_Phasen'!$D$68 -> 48400 | H26: Nutzerbasis / 100
B27: P6 Abschluss & MVP-Entscheid | C27: =VLOOKUP($B27,'04_PoC_MVP_Phasen'!$B$7:$L$22,11,FALSE)*'04_PoC_MVP_Phasen'!$D$64 -> 8500 | D27: =VLOOKUP($B27,'04_PoC_MVP_Phasen'!$B$7:$L$22,11,FALSE)*'04_PoC_MVP_Phasen'!$D$66 -> 11500 | E27: =VLOOKUP($B27,'04_PoC_MVP_Phasen'!$B$7:$L$22,11,FALSE)*'04_PoC_MVP_Phasen'!$D$67 -> 12000 | F27: =VLOOKUP($B27,'04_PoC_MVP_Phasen'!$B$7:$L$22,11,FALSE)*'04_PoC_MVP_Phasen'!$D$65 -> 10000 | G27: =VLOOKUP($B27,'04_PoC_MVP_Phasen'!$B$7:$L$22,11,FALSE)*'04_PoC_MVP_Phasen'!$D$68 -> 11000 | H27: Puffer auf PD-Zwischensumme
B28: P7 PoC-Dokumentation & Go/No-Go Vorlage | C28: =VLOOKUP($B28,'04_PoC_MVP_Phasen'!$B$7:$L$22,11,FALSE)*'04_PoC_MVP_Phasen'!$D$64 -> 5100 | D28: =VLOOKUP($B28,'04_PoC_MVP_Phasen'!$B$7:$L$22,11,FALSE)*'04_PoC_MVP_Phasen'!$D$66 -> 6900 | E28: =VLOOKUP($B28,'04_PoC_MVP_Phasen'!$B$7:$L$22,11,FALSE)*'04_PoC_MVP_Phasen'!$D$67 -> 7200 | F28: =VLOOKUP($B28,'04_PoC_MVP_Phasen'!$B$7:$L$22,11,FALSE)*'04_PoC_MVP_Phasen'!$D$65 -> 6000 | G28: =VLOOKUP($B28,'04_PoC_MVP_Phasen'!$B$7:$L$22,11,FALSE)*'04_PoC_MVP_Phasen'!$D$68 -> 6600 | H28: Einmalige Lizenzen / Tooling / Environments
B30: Externe Personentage gesamt | C30: =SUM('04_PoC_MVP_Phasen'!D22,'04_PoC_MVP_Phasen'!G22:J22)*'04_PoC_MVP_Phasen'!$D$64 -> 91.375 | D30: =SUM('04_PoC_MVP_Phasen'!D22,'04_PoC_MVP_Phasen'!G22:J22)*'04_PoC_MVP_Phasen'!$D$66 -> 123.625 | E30: =SUM('04_PoC_MVP_Phasen'!D22,'04_PoC_MVP_Phasen'!G22:J22)*'04_PoC_MVP_Phasen'!$D$67 -> 129 | F30: =SUM('04_PoC_MVP_Phasen'!D22,'04_PoC_MVP_Phasen'!G22:J22)*'04_PoC_MVP_Phasen'!$D$65 -> 107.5 | G30: =SUM('04_PoC_MVP_Phasen'!D22,'04_PoC_MVP_Phasen'!G22:J22)*'04_PoC_MVP_Phasen'!$D$68 -> 118.25 | H30: Relevant für externe Delivery-Steuerung
B31: Interne Personentage gesamt | C31: =SUM('04_PoC_MVP_Phasen'!E22,'04_PoC_MVP_Phasen'!F22)*'04_PoC_MVP_Phasen'!$D$64 -> 34.85 | D31: =SUM('04_PoC_MVP_Phasen'!E22,'04_PoC_MVP_Phasen'!F22)*'04_PoC_MVP_Phasen'!$D$66 -> 47.15 | E31: =SUM('04_PoC_MVP_Phasen'!E22,'04_PoC_MVP_Phasen'!F22)*'04_PoC_MVP_Phasen'!$D$67 -> 49.2 | F31: =SUM('04_PoC_MVP_Phasen'!E22,'04_PoC_MVP_Phasen'!F22)*'04_PoC_MVP_Phasen'!$D$65 -> 41 | G31: =SUM('04_PoC_MVP_Phasen'!E22,'04_PoC_MVP_Phasen'!F22)*'04_PoC_MVP_Phasen'!$D$68 -> 45.1 | H31: Relevante Business-/IT-Last intern
B32: Total Implementierungsinvestition | C32: =SUM(C21:C28) -> 182750 | D32: =SUM(D21:D28) -> 247250 | E32: =SUM(E21:E28) -> 258000 | F32: =SUM(F21:F28) -> 215000 | G32: =SUM(G21:G28) -> 236500 | H32: Einmalige Investition Y0
B33: Geschätzte PoC-Dauer | C33: =IFERROR(MAX(2,ROUNDUP(C30/(2*25),0)),0) -> 2 | D33: =IFERROR(MAX(2,ROUNDUP(D30/(2*25),0)),0) -> 3 | E33: =IFERROR(MAX(2,ROUNDUP(E30/(2*25),0)),0) -> 3 | F33: =IFERROR(MAX(2,ROUNDUP(F30/(2*25),0)),0) -> 3 | G33: =IFERROR(MAX(2,ROUNDUP(G30/(2*25),0)),0) -> 3 | H33: Grobe Schätzung auf Basis externer PD und paralleler Workstreams
B35: MVP Kosten
B36: ── Projektstart und Organisation ────── | C36: ='04_PoC_MVP_Phasen'!$L$30*'04_PoC_MVP_Phasen'!$D$64 -> 162180 | D36: ='04_PoC_MVP_Phasen'!$L$30*'04_PoC_MVP_Phasen'!$D$66 -> 219420 | E36: ='04_PoC_MVP_Phasen'!$L$30*'04_PoC_MVP_Phasen'!$D$67 -> 228960 | F36: ='04_PoC_MVP_Phasen'!$L$30*'04_PoC_MVP_Phasen'!$D$65 -> 190800 | G36: ='04_PoC_MVP_Phasen'!$L$30*'04_PoC_MVP_Phasen'!$D$68 -> 209880
B37: ── INTEGRATIONEN ─────────────── | C37: ='04_PoC_MVP_Phasen'!$L$35*'04_PoC_MVP_Phasen'!$D$64 -> 100300 | D37: ='04_PoC_MVP_Phasen'!$L$35*'04_PoC_MVP_Phasen'!$D$66 -> 135700 | E37: ='04_PoC_MVP_Phasen'!$L$35*'04_PoC_MVP_Phasen'!$D$67 -> 141600 | F37: ='04_PoC_MVP_Phasen'!$L$35*'04_PoC_MVP_Phasen'!$D$65 -> 118000 | G37: ='04_PoC_MVP_Phasen'!$L$35*'04_PoC_MVP_Phasen'!$D$68 -> 129800
B38: ── USE CASES ─────────────────── | C38: ='04_PoC_MVP_Phasen'!$L$42*'04_PoC_MVP_Phasen'!$D$64 -> 205700 | D38: ='04_PoC_MVP_Phasen'!$L$42*'04_PoC_MVP_Phasen'!$D$66 -> 278300 | E38: ='04_PoC_MVP_Phasen'!$L$42*'04_PoC_MVP_Phasen'!$D$67 -> 290400 | F38: ='04_PoC_MVP_Phasen'!$L$42*'04_PoC_MVP_Phasen'!$D$65 -> 242000 | G38: ='04_PoC_MVP_Phasen'!$L$42*'04_PoC_MVP_Phasen'!$D$68 -> 266200
B39: ── ABSCHLUSS ─────────────────── | C39: ='04_PoC_MVP_Phasen'!$L$51*'04_PoC_MVP_Phasen'!$D$64 -> 198900 | D39: ='04_PoC_MVP_Phasen'!$L$51*'04_PoC_MVP_Phasen'!$D$66 -> 269100 | E39: ='04_PoC_MVP_Phasen'!$L$51*'04_PoC_MVP_Phasen'!$D$67 -> 280800 | F39: ='04_PoC_MVP_Phasen'!$L$51*'04_PoC_MVP_Phasen'!$D$65 -> 234000 | G39: ='04_PoC_MVP_Phasen'!$L$51*'04_PoC_MVP_Phasen'!$D$68 -> 257400
B40: Externe Personentage gesamt | C40: =SUM('04_PoC_MVP_Phasen'!D58,'04_PoC_MVP_Phasen'!G58:J58)*'04_PoC_MVP_Phasen'!D64 -> 303.79 | D40: =SUM('04_PoC_MVP_Phasen'!D58,'04_PoC_MVP_Phasen'!G58:J58)*'04_PoC_MVP_Phasen'!D66 -> 411.01 | E40: =SUM('04_PoC_MVP_Phasen'!D58,'04_PoC_MVP_Phasen'!G58:J58)*'04_PoC_MVP_Phasen'!D67 -> 428.88 | F40: =SUM('04_PoC_MVP_Phasen'!D58,'04_PoC_MVP_Phasen'!G58:J58)*'04_PoC_MVP_Phasen'!D65 -> 357.4 | G40: =SUM('04_PoC_MVP_Phasen'!D58,'04_PoC_MVP_Phasen'!G58:J58)*'04_PoC_MVP_Phasen'!D68 -> 393.14
B41: Interne Personentage gesamt | C41: =SUM('04_PoC_MVP_Phasen'!E58:F58)*'04_PoC_MVP_Phasen'!D64 -> 110.5 | D41: =SUM('04_PoC_MVP_Phasen'!E58:F58)*'04_PoC_MVP_Phasen'!D66 -> 149.5 | E41: =SUM('04_PoC_MVP_Phasen'!E58:F58)*'04_PoC_MVP_Phasen'!D67 -> 156 | F41: =SUM('04_PoC_MVP_Phasen'!E58:F58)*'04_PoC_MVP_Phasen'!D65 -> 130 | G41: =SUM('04_PoC_MVP_Phasen'!E58:F58)*'04_PoC_MVP_Phasen'!D68 -> 143
B42: Total Implementierungsinvestition | C42: =SUM(C36:C39) -> 667080 | D42: =SUM(D36:D39) -> 902520 | E42: =SUM(E36:E39) -> 941760 | F42: =SUM(F36:F39) -> 784800 | G42: =SUM(G36:G39) -> 863280
B43: Geschätzte MVP-Dauer | C43: =IFERROR(MAX(2,ROUNDUP(C40/(1.5*25),0)),0) -> 9 | D43: =IFERROR(MAX(2,ROUNDUP(D40/(1.5*25),0)),0) -> 11 | E43: =IFERROR(MAX(2,ROUNDUP(E40/(1.5*25),0)),0) -> 12 | F43: =IFERROR(MAX(2,ROUNDUP(F40/(1.5*25),0)),0) -> 10 | G43: =IFERROR(MAX(2,ROUNDUP(G40/(1.5*25),0)),0) -> 11
B45: 3) Steady-State OPEX (Y4) – annualisierte Sicht
B46: Kostenbaustein | C46: Copilot Studio | D46: Azure Komponenten | E46: Open Source auf Azure | F46: GCP Vertex AI | G46: GCP Komponenten | H46: Kommentar
...

Sheet 06_NUTZEN_MODELL
B2: Nutzenmodell: Landi Top-down, Workshop Bottom-up und kommerzielle Hebel
B4: 1) Landi Top-down-Nutzenmodell (operativ / Effizienz)
B5: Nutzenhebel | C5: Treiber / Fälle p.a. | D5: Modell CHF p.a. | E5: Landi Referenz CHF p.a. | F5: Ausgewählt CHF p.a. | G5: Stunden p.a. | H5: FTE / AE p.a. | I5: Kommentar
B6: Unnötige Service-Aufträge vermeiden | C6: =IF('02_INPUTS'!D54>0,'02_INPUTS'!D54,'02_INPUTS'!D50*'02_INPUTS'!D51) -> 13400 | D6: =C6*'02_INPUTS'!D52/60*'02_INPUTS'!D39 -> 282516.67 | E6: 281000 | F6: =IF(D6>0,D6,C6) -> 282516.67 | G6: =C6*'02_INPUTS'!D52/60 -> 5136.6667 | H6: =G6/'02_INPUTS'!D41 -> 2.8537037 | I6: Referenz: 13’400 SA / CHF 281k
B7: Admin-Aufwand retournierte SA reduzieren | C7: ='02_INPUTS'!D50 -> 50690 | D7: =C7*'02_INPUTS'!D53/60*'02_INPUTS'!D40 -> 101380 | E7: 97620 | F7: =IF(D7>0,D7,C7) -> 101380 | G7: =C7*'02_INPUTS'!D53/60 -> 1689.6667 | H7: =G7/'02_INPUTS'!D41 -> 0.9387037 | I7: Landi Referenz: 2 Min pro retournierter SA
B8: Direktgutschriften reduzieren | C8: =IF('02_INPUTS'!D62>0,'02_INPUTS'!D62,'02_INPUTS'!D59*'02_INPUTS'!D61) -> 20475 | D8: =IF('02_INPUTS'!D62>0,C8*('02_INPUTS'!D60/'02_INPUTS'!D59),'02_INPUTS'!D60*'02_INPUTS'!D61) -> 562867.65 | E8: ='02_INPUTS'!D63 -> 697289 | F8: =IF(D8>0,D8,C8) -> 562867.65 | G8: 0 | H8: =G8/'02_INPUTS'!D41 -> 0 | I8: Landi Referenz: CHF 697’289
B9: Schriftliche Anfragen vermeiden | C9: =IF('02_INPUTS'!D55>0,'02_INPUTS'!D55,0) -> 40620 | D9: =C9*'02_INPUTS'!D56/60*'02_INPUTS'!D40 -> 406200 | E9: 406200 | F9: =IF(D9>0,D9,C9) -> 406200 | G9: =C9*'02_INPUTS'!D56/60 -> 6770 | H9: =G9/'02_INPUTS'!D41 -> 3.7611111 | I9: Landi Referenz: 40’620 Anfragen
B10: Aufwand auf restlichen Anfragen reduzieren | C10: =IF('02_INPUTS'!D58>0,'02_INPUTS'!D58,MAX('02_INPUTS'!D48-C9,0)) -> 162480 | D10: =C10*'02_INPUTS'!D56*'02_INPUTS'!D57/60*'02_INPUTS'!D40 -> 541058.4 | E10: 541080 | F10: =IF(D10>0,D10,C10) -> 541058.4 | G10: =C10*'02_INPUTS'!D56*'02_INPUTS'!D57/60 -> 9017.64 | H10: =G10/'02_INPUTS'!D41 -> 5.0098 | I10: Landi Referenz: 162’480 Restanfragen
B11: Brutto-Effizienzpotenzial p.a. | F11: =SUM(F6:F10) -> 1894022.7 | I11: Brutto = Summe der fünf Landi-Top-down-Kategorien
B12: Konservativer Wirkungsgrad Effizienz | F12: ='02_INPUTS'!D64 -> 0.75 | I12: Default 75% gemäss Legacy-Annahme
B13: Konservatives Effizienzpotenzial p.a. | F13: =F11*F12 -> 1420517 | I13: Basiscase Effizienzpotenzial p.a.
B14: Stunden gesamt p.a. | F14: =SUM(G6:G10) -> 22613.973 | I14: Rechnerische Stundenfreisetzung
B15: FTE / AE gesamt | F15: =SUM(H6:H10) -> 12.563319 | H15: =SUM(H6:H10) -> 12.563319 | I15: Rechnerische FTE-Äquivalente
B18: 2) Workshop Bottom-up Crosscheck
B19: Task & Business Context | E19: Volumen / Zeit / Arbeitsnutzen (Nutzen durch schnellere Ausführung) | U19: Outcome-basierter Nutzen (Nutzen durch vermiedene unnötige Service-Arbeiten oder Zusatzumsatz)
B20: ID | C20: Task | D20: Primärer Business Case | E20: Cases CH | F20: Cases Laden | G20: Adoptionsrate (Landi CH) | H20: Adoptionsrate (Landi Laden) | I20: Erfolgsquote KI | J20: KI-genutzte Cases (Landi CH) p.a. | K20: Erfolgreiche Cases (Landi CH) p.a. | L20: Erfolgreiche Cases (Landi Laden) p.a. | M20: KI-genutzte Cases (Landi Laden) | N20: Zeitaufwand heute (min) | O20: Zeitaufwand mit AI (min) | P20: Eingesparte Zeit (min) | Q20: Kosten pro Minute Landi CH (CHF) | R20: Kosten pro Minute Landi Laden (CHF) | S20: Arbeitsnutzen p.a. Landi CH (CHF) | T20: Arbeitsnutzen p.a. Landi Laden (CHF) | U20: Vermiedene Serviceaufträge / Jahr | V20: Kosten pro Serviceauftrag (CHF) | W20: Nutzen vermiedene Serviceaufträge (CHF) | X20: Vermiedene Direktgutschriften / Jahr | Y20: Kosten pro Direktgutschrift (CHF) | Z20: Nutzen vermiedene Direktgutschriften (CHF) | AA20: Zusätzlicher Deckungsbeitrag p.a. (CHF) | AB20: Zusätzliche Ersatzteilverkäufe / Jahr | AC20: Nutzen pro Ersatzteilverkauf (CHF) | AD20: Nutzen zusätzliche Ersatzteilverkäufe (CHF) | AE20: Landi CH-Bruttonutzen p.a. (CHF) | AF20: Landi Laden-Bruttonutzen p.a. (CHF) | AG20: Gesamt-Bruttonutzen p.a. (CHF)
B21: 1 | C21: Produkt identifizieren | D21: Bearbeitungszeit reduzieren | E21: 10000 | F21: 500000 | G21: 0.95 | H21: 0.7 | I21: 0.85 | J21: =E21*G21 -> 9500 | K21: =J21*I21 -> 8075 | L21: =M21*I21 -> 297500 | M21: =F21*H21 -> 350000 | N21: 2 | O21: 0.5 | P21: =MAX(N21-O21,0) -> 1.5 | Q21: 1 | R21: 0.83 | S21: =K21*P21*Q21 -> 12112.5 | T21: =L21*P21*R21 -> 370387.5 | W21: =U21*V21 -> 0 | Z21: =X21*Y21 -> 0 | AA21: 0 | AE21: =SUM(S21,W21,Z21,AA21, AD21) -> 12112.5 | AF21: =SUM(T21) -> 370387.5 | AG21: =SUM(S21,T21,W21,Z21,AA21, AD21) -> 382500
B22: 2 | C22: Produktinformationen bereitstellen | D22: Bearbeitungszeit reduzieren | E22: 10000 | F22: 500000 | G22: 0.95 | H22: 0.7 | I22: 0.95 | J22: =E22*G22 -> 9500 | K22: =J22*I22 -> 9025 | L22: =M22*I22 -> 332500 | M22: =F22*H22 -> 350000 | N22: 3 | O22: 1 | P22: =MAX(N22-O22,0) -> 2 | Q22: 1 | R22: 0.83 | S22: =K22*P22*Q22 -> 18050 | T22: =L22*P22*R22 -> 551950 | U22: 0 | V22: 0 | W22: =U22*V22 -> 0 | X22: 0 | Y22: 0 | Z22: =X22*Y22 -> 0 | AA22: 0 | AE22: =SUM(S22,W22,Z22,AA22, AD22) -> 18050 | AF22: =SUM(T22) -> 551950 | AG22: =SUM(S22,T22,W22,Z22,AA22, AD22) -> 570000
B23: 3 | C23: Diagnose durchführen | D23: Reduktion der Anfragen | E23: 58000 | F23: 101000 | G23: 1 | H23: 1 | I23: 0.95 | J23: =E23*G23 -> 58000 | K23: =J23*I23 -> 55100 | L23: =M23*I23 -> 95950 | M23: =F23*H23 -> 101000 | N23: 5 | O23: 5 | P23: =MAX(N23-O23,0) -> 0 | Q23: 1 | R23: 0.83 | S23: =K23*P23*Q23 -> 0 | T23: =L23*P23*R23 -> 0 | U23: 6500 | V23: 47.9 | W23: =U23*V23 -> 311350 | X23: 10000 | Y23: 27.5 | Z23: =X23*Y23 -> 275000 | AA23: 0 | AE23: =SUM(S23,W23,Z23,AA23, AD23) -> 586350 | AF23: =SUM(T23) -> 0 | AG23: =SUM(S23,T23,W23,Z23,AA23, AD23) -> 586350
B24: 4 | C24: Handlungsoptionen empfehlen | D24: Serviceaufträge vermeiden | E24: 58000 | F24: 101000 | G24: 1 | H24: 1 | I24: 0.95 | J24: =E24*G24 -> 58000 | K24: =J24*I24 -> 55100 | L24: =M24*I24 -> 95950 | M24: =F24*H24 -> 101000 | N24: 5 | O24: 5 | P24: =MAX(N24-O24,0) -> 0 | Q24: 1 | R24: 0.83 | S24: =K24*P24*Q24 -> 0 | T24: =L24*P24*R24 -> 0 | U24: 6500 | V24: 47.9 | W24: =U24*V24 -> 311350 | X24: 10000 | Y24: 27.5 | Z24: =X24*Y24 -> 275000 | AA24: 0 | AE24: =SUM(S24,W24,Z24,AA24, AD24) -> 586350 | AF24: =SUM(T24) -> 0 | AG24: =SUM(S24,T24,W24,Z24,AA24, AD24) -> 586350
B25: 5 | C25: Ersatzteil identifizieren | D25: Ersatzteilumsatz erhöhen | E25: 5000 | F25: 50000 | G25: 0.95 | H25: 0.7 | I25: 0.95 | J25: =E25*G25 -> 4750 | K25: =J25*I25 -> 4512.5 | L25: =M25*I25 -> 33250 | M25: =F25*H25 -> 35000 | N25: 1 | O25: 0.5 | P25: =MAX(N25-O25,0) -> 0.5 | Q25: 1 | R25: 0.83 | S25: =K25*P25*Q25 -> 2256.25 | T25: =L25*P25*R25 -> 13798.75 | U25: 0 | V25: 0 | W25: =U25*V25 -> 0 | X25: 0 | Y25: 0 | Z25: =X25*Y25 -> 0 | AA25: 0 | AB25: =236874*0.1 -> 23687.4 | AC25: =6*0.25 -> 1.5 | AD25: =AB25*AC25 -> 35531.1 | AE25: =SUM(S25,W25,Z25,AA25, AD25) -> 37787.35 | AF25: =SUM(T25) -> 13798.75 | AG25: =SUM(S25,T25,W25,Z25,AA25, AD25) -> 51586.1
B26: 8 | C26: Garantie prüfen | D26: Direktgutschriften vermeiden | E26: 66000 | F26: 101000 | G26: 1 | H26: 1 | I26: 0.95 | J26: =E26*G26 -> 66000 | K26: =J26*I26 -> 62700 | L26: =M26*I26 -> 95950 | M26: =F26*H26 -> 101000 | N26: 2 | O26: 1.5 | P26: =MAX(N26-O26,0) -> 0.5 | Q26: 1 | R26: 0.83 | S26: =K26*P26*Q26 -> 31350 | T26: =L26*P26*R26 -> 39819.25 | U26: 0 | V26: 0 | W26: =U26*V26 -> 0 | X26: 0 | Y26: 0 | Z26: =X26*Y26 -> 0 | AA26: 0 | AE26: =SUM(S26,W26,Z26,AA26, AD26) -> 31350 | AF26: =SUM(T26) -> 39819.25 | AG26: =SUM(S26,T26,W26,Z26,AA26, AD26) -> 71169.25
B27: 9 | C27: Anfrage (Case) vorbereiten | D27: Bearbeitungszeit reduzieren | E27: 100000 | F27: 200000 | G27: 0.95 | H27: 0.7 | I27: 0.95 | J27: =E27*G27 -> 95000 | K27: =J27*I27 -> 90250 | L27: =M27*I27 -> 133000 | M27: =F27*H27 -> 140000 | N27: 2 | O27: 1 | P27: =MAX(N27-O27,0) -> 1 | Q27: 1 | R27: 0.83 | S27: =K27*P27*Q27 -> 90250 | T27: =L27*P27*R27 -> 110390 | U27: 0 | V27: 0 | W27: =U27*V27 -> 0 | X27: 0 | Y27: 0 | Z27: =X27*Y27 -> 0 | AA27: 0 | AE27: =SUM(S27,W27,Z27,AA27, AD27) -> 90250 | AF27: =SUM(T27) -> 110390 | AG27: =SUM(S27,T27,W27,Z27,AA27, AD27) -> 200640
B28: 10 | C28: Dokumentation optimieren | D28: Dokumentationsqualität steigern | E28: 47000 | F28: 0 | G28: 1 | I28: 0.95 | J28: =E28*G28 -> 47000 | K28: =J28*I28 -> 44650 | L28: =M28*I28 -> 0 | M28: =F28*H28 -> 0 | N28: 3.5 | O28: 2 | P28: =MAX(N28-O28,0) -> 1.5 | Q28: 1 | R28: 0.83 | S28: =K28*P28*Q28 -> 66975 | T28: =L28*P28*R28 -> 0 | U28: 0 | V28: 0 | W28: =U28*V28 -> 0 | X28: 0 | Y28: 0 | Z28: =X28*Y28 -> 0 | AA28: 0 | AE28: =SUM(S28,W28,Z28,AA28, AD28) -> 66975 | AF28: =SUM(T28) -> 0 | AG28: =SUM(S28,T28,W28,Z28,AA28, AD28) -> 66975
B29: TOTAL | E29: =SUM(E21:E28) -> 354000 | F29: =SUM(F21:F28) -> 1553000 | G29: =AVERAGE(G21:G28) -> 0.975 | H29: =AVERAGE(H21:H28) -> 0.82857143 | I29: =AVERAGE(I21:I28) -> 0.9375 | J29: =SUM(J21:J28) -> 347750 | K29: =SUM(K21:K28) -> 329412.5 | L29: =SUM(L21:L28) -> 1084100 | M29: =SUM(M21:M28) -> 1178000 | N29: =AVERAGE(N21:N28) -> 2.9375 | O29: =AVERAGE(O21:O28) -> 2.0625 | P29: =AVERAGE(P21:P28) -> 0.875 | Q29: =AVERAGE(Q21:Q28) -> 1 | R29: =AVERAGE(R21:R28) -> 0.83 | S29: =SUM(S21:S28) -> 220993.75 | T29: =SUM(T21:T28) -> 1086345.5 | U29: =SUM(U21:U28) -> 13000 | V29: =AVERAGE(V23:V24) -> 47.9 | W29: =SUM(W21:W28) -> 622700 | X29: =SUM(X21:X28) -> 20000 | Y29: =AVERAGE(Y23:Y24) -> 27.5 | Z29: =SUM(Z21:Z28) -> 550000 | AE29: =SUM(AE21:AE28) -> 1429224.9 | AF29: =SUM(AF21:AF28) -> 1086345.5 | AG29: =SUM(AG21:AG28) -> 2515570.4
B30: Interpretation: Der Bottom-up Workshop ergibt rund CHF 2.52 Mio. Bruttonutzen p.a. für die quantifizierten Tasks für die Landi CH und die Landi Läden. Die Landi CH liegt mit einem geschätzten Nutzen von 1.42 Mio. genau im selben Bereich wie die Top-down_Schätzung. Die Legacy-Annahme von CHF 1.52 Mio. p.a. (75% Wirkung) ist daher realistisch. | I30: Bottom-up liegt über Top-down und bestätigt, dass die Legacy-Annahme konservativ ist.
B32: 3) Kommerzielle Upside und ausgewählter Basiscase
B33: Hebel | C33: Treiber | D33: Brutto CHF p.a. | E33: Kommentar
B34: landi.ch Conversion-Uplift (aktuell → neu) | C34: =MAX('02_INPUTS'!D71*'02_INPUTS'!D75-'02_INPUTS'!D71*'02_INPUTS'!D73,0) -> 18004 | D34: =C34*'02_INPUTS'!D67*'02_INPUTS'!D77 -> 475100.35 | E34: Primäre eCommerce-Upside
B35: landi.ch Conversion-Uplift (Budget 2026 → neu) | C35: =MAX('02_INPUTS'!D72*'02_INPUTS'!D75-'02_INPUTS'!D72*'02_INPUTS'!D74,0) -> 14125 | D35: =C35*'02_INPUTS'!D69*'02_INPUTS'!D77 -> 379614.74 | E35: Alternative Sicht vs Budgetziel
B36: Stationärer Basket-Uplift | C36: ='02_INPUTS'!D76*'02_INPUTS'!D78*'02_INPUTS'!D79 -> 0 | D36: =C36*'02_INPUTS'!D77 -> 0 | E36: Nur aktivieren, wenn Attribution belastbar
B37: Stationäre Frequenz-Uplift | C37: ='02_INPUTS'!D76*'02_INPUTS'!D80 -> 0 | D37: =C37*'02_INPUTS'!D77 -> 0 | E37: Konservativ default = 0
B38: Ersatzteil-Umsatz-Uplift | C38: ='02_INPUTS'!D83*'02_INPUTS'!D85 -> 0 | D38: =C38*'02_INPUTS'!D84 -> 0 | E38: Aus Workshop-Spare-Parts-Revenue ableitbar
B39: Brutto kommerzielle Upside p.a. | D39: =SUM(D34,D36:D38) -> 475100.35 | E39: Budget-Alternative in D34 bewusst nicht im Basistotal
B40: Konservative kommerzielle Upside p.a. | D40: =D39*'02_INPUTS'!D82 -> 237550.18 | E40: Vor Szenario-Realisierung, aber nach Haircut
B41: Ausgewählter Basiscase p.a. | D41: =F13+D40*'02_INPUTS'!D81 -> 1420517 | E41: Effizienz + optionale kommerzielle Upside
B42: Optionales Potenzial p.a. inkl. kommerzieller Upside | D42: =F13+D40 -> 1658067.2 | E42: Nur zur Sensitivität
B43: Legacy konservativer Nutzen p.a. | D43: 1517392 | E43: Aus Altmodell / Landi Working Assumption
B44: Delta ausgewählter Basiscase vs Legacy | D44: =D41-D43 -> -96874.96 | E44: Soll nahe 0 bleiben bei deaktivierter Upside
B45: Workshop brutto p.a. | D45: =AE29 -> 1429224.9 | E45: Bottom-up Crosscheck
...

Sheet 07_VALUE_CASE
B2: Szenariobasierter Wertbeitrag, Payback und strategische Einordnung
B4: Messgrösse | C4: Copilot Studio | D4: Azure Komponenten | E4: Open Source auf Azure | F4: GCP Vertex AI | G4: GCP Komponenten | H4: Kommentar
B5: Realisierungsfaktor Effizienznutzen | C5: ='03_SZENARIOS'!C45 -> 0.85 | D5: ='03_SZENARIOS'!D45 -> 0.95 | E5: ='03_SZENARIOS'!E45 -> 0.95 | F5: ='03_SZENARIOS'!F45 -> 0.9 | G5: ='03_SZENARIOS'!G45 -> 0.95 | H5: Aus Szenario-Narrativ abgeleitet; editierbar
B6: Realisierungsfaktor kommerzielle Upside | C6: ='03_SZENARIOS'!C46 -> 0.45 | D6: ='03_SZENARIOS'!D46 -> 0.85 | E6: ='03_SZENARIOS'!E46 -> 0.9 | F6: ='03_SZENARIOS'!F46 -> 0.7 | G6: ='03_SZENARIOS'!G46 -> 0.85 | H6: Kommerzielle Hebel brauchen tiefere Integration
B7: Steady-state Effizienznutzen p.a. | C7: ='06_NUTZEN_MODELL'!F13*C5 -> 1207439.5 | D7: ='06_NUTZEN_MODELL'!F13*D5 -> 1349491.2 | E7: ='06_NUTZEN_MODELL'!F13*E5 -> 1349491.2 | F7: ='06_NUTZEN_MODELL'!F13*F5 -> 1278465.3 | G7: ='06_NUTZEN_MODELL'!F13*G5 -> 1349491.2 | H7: Nur konservativer Effizienznutzen
B8: Steady-state kommerzielle Upside p.a. | C8: ='06_NUTZEN_MODELL'!D40*C6*'02_INPUTS'!D81 -> 0 | D8: ='06_NUTZEN_MODELL'!D40*D6*'02_INPUTS'!D81 -> 0 | E8: ='06_NUTZEN_MODELL'!D40*E6*'02_INPUTS'!D81 -> 0 | F8: ='06_NUTZEN_MODELL'!D40*F6*'02_INPUTS'!D81 -> 0 | G8: ='06_NUTZEN_MODELL'!D40*G6*'02_INPUTS'!D81 -> 0 | H8: Kommerzielle Upside nur bei aktiviertem Schalter
B9: Steady-state Gesamtpotenzial p.a. | C9: =C7+C8 -> 1207439.5 | D9: =D7+D8 -> 1349491.2 | E9: =E7+E8 -> 1349491.2 | F9: =F7+F8 -> 1278465.3 | G9: =G7+G8 -> 1349491.2 | H9: Steady-state p.a.
B10: Ramp-up Faktor Y1 | C10: =IFERROR('05_KOSTEN_MODELL'!C9/'05_KOSTEN_MODELL'!F9,0) -> 0.38888889 | D10: =IFERROR('05_KOSTEN_MODELL'!C9/'05_KOSTEN_MODELL'!F9,0) -> 0.38888889 | E10: =IFERROR('05_KOSTEN_MODELL'!C9/'05_KOSTEN_MODELL'!F9,0) -> 0.38888889 | F10: =IFERROR('05_KOSTEN_MODELL'!C9/'05_KOSTEN_MODELL'!F9,0) -> 0.38888889 | G10: =IFERROR('05_KOSTEN_MODELL'!C9/'05_KOSTEN_MODELL'!F9,0) -> 0.38888889 | H10: Usage-Ramp-up als Benefit-Ramp-up
B11: Ramp-up Faktor Y2 | C11: =IFERROR('05_KOSTEN_MODELL'!D9/'05_KOSTEN_MODELL'!F9,0) -> 0.66666667 | D11: =IFERROR('05_KOSTEN_MODELL'!D9/'05_KOSTEN_MODELL'!F9,0) -> 0.66666667 | E11: =IFERROR('05_KOSTEN_MODELL'!D9/'05_KOSTEN_MODELL'!F9,0) -> 0.66666667 | F11: =IFERROR('05_KOSTEN_MODELL'!D9/'05_KOSTEN_MODELL'!F9,0) -> 0.66666667 | G11: =IFERROR('05_KOSTEN_MODELL'!D9/'05_KOSTEN_MODELL'!F9,0) -> 0.66666667 | H11: Usage-Ramp-up als Benefit-Ramp-up
B12: Ramp-up Faktor Y3 | C12: =IFERROR('05_KOSTEN_MODELL'!E9/'05_KOSTEN_MODELL'!F9,0) -> 0.83333333 | D12: =IFERROR('05_KOSTEN_MODELL'!E9/'05_KOSTEN_MODELL'!F9,0) -> 0.83333333 | E12: =IFERROR('05_KOSTEN_MODELL'!E9/'05_KOSTEN_MODELL'!F9,0) -> 0.83333333 | F12: =IFERROR('05_KOSTEN_MODELL'!E9/'05_KOSTEN_MODELL'!F9,0) -> 0.83333333 | G12: =IFERROR('05_KOSTEN_MODELL'!E9/'05_KOSTEN_MODELL'!F9,0) -> 0.83333333 | H12: Usage-Ramp-up als Benefit-Ramp-up
B13: Ramp-up Faktor Y4 | C13: 1 | D13: 1 | E13: 1 | F13: 1 | G13: 1 | H13: Usage-Ramp-up als Benefit-Ramp-up
B14: Ramp-up Faktor Y5 | C14: 1 | D14: 1 | E14: 1 | F14: 1 | G14: 1 | H14: Usage-Ramp-up als Benefit-Ramp-up
B15: 5Y kumulierter Ramp-up-Faktor | C15: =SUM(C10:C14) -> 3.8888889 | D15: =SUM(D10:D14) -> 3.8888889 | E15: =SUM(E10:E14) -> 3.8888889 | F15: =SUM(F10:F14) -> 3.8888889 | G15: =SUM(G10:G14) -> 3.8888889
B16: Kumulierter Nutzen über 5 Jahre | C16: =C9*C15 -> 4695598 | D16: =D9*D15 -> 5248021.3 | E16: =E9*E15 -> 5248021.3 | F16: =F9*F15 -> 4971809.6 | G16: =G9*G15 -> 5248021.3 | H16: 5Y Nutzen über Ramp-up
B17: Einmalige Implementierungsinvestition | C17: ='05_KOSTEN_MODELL'!C67 -> 849830 | D17: ='05_KOSTEN_MODELL'!D67 -> 1149770 | E17: ='05_KOSTEN_MODELL'!E67 -> 1199760 | F17: ='05_KOSTEN_MODELL'!F67 -> 999800 | G17: ='05_KOSTEN_MODELL'!G67 -> 1099780
B18: 5Y OPEX | C18: ='05_KOSTEN_MODELL'!H59 -> 2456048.5 | D18: ='05_KOSTEN_MODELL'!H60 -> 2030628.3 | E18: ='05_KOSTEN_MODELL'!H61 -> 1935236.5 | F18: ='05_KOSTEN_MODELL'!H62 -> 1627150.9 | G18: ='05_KOSTEN_MODELL'!H63 -> 1894791.8
B19: 5Y TCO | C19: =C17+C18 -> 3305878.5 | D19: =D17+D18 -> 3180398.3 | E19: =E17+E18 -> 3134996.5 | F19: =F17+F18 -> 2626950.9 | G19: =G17+G18 -> 2994571.8
B20: 5Y Nettowert | C20: =C16-C19 -> 1389719.5 | D20: =D16-D19 -> 2067623 | E20: =E16-E19 -> 2113024.8 | F20: =F16-F19 -> 2344858.7 | G20: =G16-G19 -> 2253449.4 | H20: Nutzen minus TCO
B21: Nettoeffekt Jahr 1 | C21: =C9*C10-'05_KOSTEN_MODELL'!C59-C17 -> -770925.05 | D21: =D9*D10-'05_KOSTEN_MODELL'!C60-D17 -> -1015153.3 | E21: =E9*E10-'05_KOSTEN_MODELL'!C61-E17 -> -1058817.1 | F21: =F9*F10-'05_KOSTEN_MODELL'!C62-F17 -> -821673.13 | G21: =G9*G10-'05_KOSTEN_MODELL'!C63-G17 -> -941184.06
